Workbook
Name \a: [1]成品current!#REF!
Name \a: [1]成品current!#REF!
Name \a: [1]成品current!#REF!
Name \a: [1]成品current!#REF!
Name \a: [1]成品current!#REF!
Name \a: [1]成品current!#REF!
Name \a: [1]成品current!#REF!
Name \a: [1]成品current!#REF!
Name \a: [1]成品current!#REF!
Name \a: [1]成品current!#REF!
Name \B: #REF!
Name \B: #REF!
Name \B: #REF!
Name \B: #REF!
Name \B: #REF!
Name \B: #REF!
Name \B: #REF!
Name \B: #REF!
Name \B: #REF!
Name \B: #REF!
Name \c: '[2]統計処理(H)'!#REF!
Name \c: '[2]統計処理(H)'!#REF!
Name \c: '[2]統計処理(H)'!#REF!
Name \c: '[2]統計処理(H)'!#REF!
Name \c: '[2]統計処理(H)'!#REF!
Name \c: '[2]統計処理(H)'!#REF!
Name \c: '[2]統計処理(H)'!#REF!
Name \c: '[2]統計処理(H)'!#REF!
Name \c: '[2]統計処理(H)'!#REF!
Name \c: '[2]統計処理(H)'!#REF!
Name \D: #REF!
Name \D: #REF!
Name \D: #REF!
Name \D: #REF!
Name \D: #REF!
Name \D: #REF!
Name \D: #REF!
Name \D: #REF!
Name \D: #REF!
Name \D: #REF!
Name \e: '[2]統計処理(H)'!#REF!
Name \e: '[2]統計処理(H)'!#REF!
Name \e: '[2]統計処理(H)'!#REF!
Name \e: '[2]統計処理(H)'!#REF!
Name \e: '[2]統計処理(H)'!#REF!
Name \e: '[2]統計処理(H)'!#REF!
Name \e: '[2]統計処理(H)'!#REF!
Name \e: '[2]統計処理(H)'!#REF!
Name \e: '[2]統計処理(H)'!#REF!
Name \e: '[2]統計処理(H)'!#REF!
Name \M: #REF!
Name \M: #REF!
Name \M: #REF!
Name \M: #REF!
Name \M: #REF!
Name \M: #REF!
Name \M: #REF!
Name \M: #REF!
Name \M: #REF!
Name \M: #REF!

Sheet Project Milestone
A1: SMT line | B1: 3A
A2: FATP line | B2: 4A
A3: Package line | B3: 5M
A5: Project | B5: Site | C5: Line | D5: Retrofit timing | E5: Transfer to VN | F5: Line set up & debug | G5: Line qual | H5: FATP Trial run date | I5: FAT Trial run q'ty | J5: Packing trial run | K5: Line qual Approval | L5: SMT OP qual approval | M5: FATP OP qual approval | N5: Shift | O5: PVT SMT | P5: PVT FATP Ramp | Q5: FAI report submission | R5: FAI approval | S5: Cut-off data for reports | T5: REL | U5: CET test report submission | V5: Internal PO shipment date | W5: Internal PO-validation result | X5: Submit reports date | Y5: OK2ship | Z5: FFS | AA5: Remark
A6: Calypso | B6: VN | C6: Line 1: POR line SMT * 1 + FATP * 1 + Packing * 1 | D6: / | E6: / | F6: POR line (Use from DVT) | G6: 11/03~11/12 | H6: 45973 | I6: 60pcs (5 panels) | J6: 12pcs | K6: SMT: 11/13/2025 FATP: 11/12/2025 Packing: 11/15/2025 | L6: 45974 | M6: 45976 | N6: DS | O6: 45975 | P6: 11/17~12/02 | Q6: 45976 | R6: 45976 | S6: 45992 | T6: TBD | U6: 45992 | V6: WK11/16: 1681x (Before OK2S) WK12/07: 940x (after OK2S) | W6: TBD | X6: 45993 | Y6: 45999 | Z6: 46001 | AA6: Ramp up to 95% eficiency until cut off date
N7: NS | P7: 11/18~12/03 | Q7: 11/19/2025 9:00am | R7: 11/19/2025 10:00am | AA7: Ramp up to 95% eficiency until cut off date
C8: Line 2: FATP Retrofit from VN Sheldon SMT * 1 + FATP * 1 + Packing * 1 | D8: 09/15~10/18 | E8: 10/20~11/06 | F8: 11/07~11/11 | G8: 11/12~11/15 | H8: 45978 | I8: 60pcs (5 panels) | J8: 12pcs | K8: SMT: 11/18/2025 FATP: 11/18/2025 Packing: 11/19/2025 | L8: 45979 | M8: 45980 | N8: DS | O8: 45980 | P8: 11/20~12/05 | Q8: 11/20/2025 1:00pm | R8: 11/20/2025 2:00pm | AA8: Ramp up to 85% eficiency until cut off date
N9: NS | P9: 11/21~12/06 | Q9: 11/22/2025 9:00am | R9: 11/22/2025 10:00am | AA9: Ramp up to 80% eficiency until cut off date
C10: Line 3: FATP Retrofit from LH Sheldon. (Auto HSG assembly line retrofit from Callie VN) SMT * 1 + FATP * 1 + Packing * 1 | D10: 09/15~11/08 | E10: 10/20~11/15 | F10: 11/10~11/15 | G10: 11/15~11/19 | H10: 45981 | I10: 60pcs (5 panels) | J10: 12pcs | K10: SMT: 11/22/2025 FATP: 11/21/2025 Packing: 11/24/2025 | L10: 45983 | M10: 45983 | N10: DS | O10: 45985 | P10: 11/24~12/09 | Q10: 11/24/2025 1:00pm | R10: 11/24/2025 2:00pm | AA10: Ramp up to 60% eficiency until cut off date
N11: NS | P11: 11/25~12/10 | Q11: 11/26/2025 9:00am | R11: 11/26/2025 10:00am | AA11: Ramp up to 50% eficiency until cut off date
C12: Line 4: FATP Retrofit from LH Sheldon. (Auto HSG assembly line retrofit from Callie VN) FATP * 1 + Packing * 2 | D12: 09/15~11/08 | E12: 10/20~11/15 | F12: 11/12~11/15 | G12: 11/17~11/22 | H12: 45985 | I12: 60pcs (5 panels) | J12: 12pcs/line | K12: FATP: 11/25/2025 Packing: 11/27/2025 | L12: / | M12: 45987 | N12: DS | O12: / | P12: 11/27~12/12 | Q12: 11/27/2025 1:00pm | R12: 11/27/2025 2:00pm | AA12: Ramp up to 30% eficiency until cut off date
N13: NS | P13: 11/28~12/13 | Q13: 11/29/2025 9:00am | R13: 11/29/2025 10:00am | AA13: Ramp up to 20% eficiency until cut off date
A15: Plan
A16: On-going
A17: Closed
A20: Summary:
A21: Risk:

Sheet HSG & Auto PKG line mitigation
A2: Project | B2: Site | C2: Line | D2: Process | E2: Retrofit FAB timing | F2: Transfer to VN | G2: Line set up & debug | H2: Line qual | I2: FATP Trial run date | J2: Remark
A3: Calypso | B3: VN | C3: Line 1: POR line SMT * 1 + Panel Assembly * 1 + Packing * 1 | D3: Panel Assembly | E3: / | F3: / | G3: POR line (Use from DVT) | H3: 11/03~11/12 | I3: 45973
D4: Housing Assembly
C5: Line 2: FATP Retrofit from LH Sheldon. SMT * 1 + FATP * 1 + Packing * 1 | D5: Panel Assembly | E5: 09/15~10/18 | F5: 10/20~11/01 | G5: 11/03~11/09 | H5: 11/10~11/15 | I5: 45978
D6: Housing Assembly
C7: Line 3 * Line 4: Housing 2nd line | D7: Original plan | E7: 09/01~10/18 | F7: 10/20~11/01 | G7: 11/03~11/11 | H7: 11/12~11/19 | I7: 45981
D8: Updated plan | E8: 09/01~11/08 (Delay 3 wks) | F8: 11/10~11/22 | G8: 11/24~12/02 | H8: 12/03~12/10 | I8: 46002
D9: Mitigation plan: Retrofit Callie VN housing line | E9: 10/13~11/08 | F9: / | G9: 11/10~11/13 | H9: 11/14~11/19 | I9: 45981
C10: Auto Packing line | D10: Original plan | E10: 09/14~11/15 | F10: 11/17~12/01 | G10: 12/02~12/08 | H10: 12/08~12/12 | I10: 12/13/2025
D11: Updated plan | E11: 09/14~11/29 (Delay 2 wks) | F11: 12/01~12/15 | G11: 12/16~12/22 | H11: 12/23~12/27 | I11: 46020
D12: Mitigation plan: Qualify Manual Packing 5th line in PVT | E12: / | F12: / | G12: 11/03~11/10 | H12: 11/24~11/25 | I12: 45987
A15: Summary:
A16: Risk:

Sheet Line qual Milestone
A1: PVT Auto fungible 1.0 line * 4 | R1: Actual
A3: No | B3: Process | C3: Lines | D3: Items | E3: Start date | F3: End date | G3: Lead time | H3: Status | I3: 45901 | AK3: 45931 | BM3: 45962 | CV3: 45992
I4: 45907 | P4: =I4+7 -> 45914 | W4: =P4+7 -> 45921 | AD4: =W4+7 -> 45928 | AK4: =AD4+7 -> 45935 | AR4: =AK4+7 -> 45942 | AY4: =AR4+7 -> 45949 | BF4: =AY4+7 -> 45956 | BM4: =BF4+7 -> 45963 | BT4: =BM4+7 -> 45970 | CA4: =BT4+7 -> 45977 | CH4: =CA4+7 -> 45984 | CO4: =CH4+7 -> 45991 | CV4: =CO4+7 -> 45998 | DC4: =CV4+7 -> 46005 | DJ4: =DC4+7 -> 46012 | DQ4: =DJ4+7 -> 46019
I5: 7 | J5: 8 | K5: 9 | L5: 10 | M5: 11 | N5: 12 | O5: 13 | P5: 14 | Q5: 15 | R5: 16 | S5: 17 | T5: 18 | U5: 19 | V5: 20 | W5: 21 | X5: 22 | Y5: 23 | Z5: 24 | AA5: 25 | AB5: 26 | AC5: 27 | AD5: 28 | AE5: 29 | AF5: 30 | AG5: 1 | AH5: 2 | AI5: 3 | AJ5: 4 | AK5: 5 | AL5: 6 | AM5: 7 | AN5: 8 | AO5: 9 | AP5: 10 | AQ5: 11 | AR5: 12 | AS5: 13 | AT5: 14 | AU5: 15 | AV5: 16 | AW5: 17 | AX5: 18 | AY5: 19 | AZ5: 20 | BA5: 21 | BB5: 22 | BC5: 23 | BD5: 24 | BE5: 25 | BF5: 26 | BG5: 27 | BH5: 28 | BI5: 29 | BJ5: 30 | BK5: 31 | BL5: 1 | BM5: 2 | BN5: 3 | BO5: 4 | BP5: 5 | BQ5: 6 | BR5: 7 | BS5: 8 | BT5: 9 | BU5: 10 | BV5: 11 | BW5: 12 | BX5: 13 | BY5: 14 | BZ5: 15 | CA5: 16 | CB5: 17 | CC5: 18 | CD5: 19 | CE5: 20 | CF5: 21 | CG5: 22 | CH5: 23 | CI5: 24 | CJ5: 25 | CK5: 26 | CL5: 27 | CM5: 28 | CN5: 29 | CO5: 30 | CP5: 1 | CQ5: 2 | CR5: 3 | CS5: 4 | CT5: 5 | CU5: 6 | CV5: 7 | CW5: 8 | CX5: 9 | CY5: 10 | CZ5: 11 | DA5: 12 | DB5: 13 | DC5: 14 | DD5: 15 | DE5: 16 | DF5: 17 | DG5: 18 | DH5: 19 | DI5: 20 | DJ5: 21 | DK5: 22 | DL5: 23 | DM5: 24 | DN5: 25 | DO5: 26 | DP5: 27 | DQ5: 28 | DR5: 29 | DS5: 30 | DT5: 31
A6: 1 | B6: SMT | C6: SMT S2 line | D6: Line setup (HDMI press) | E6: 45968 | F6: 45969 | G6: =+F6-E6+1 -> 2 | H6: On-going | BR6: Set up
D7: Line debug and qualification | E7: 45971 | F7: 45972 | G7: =+F7-E7+1 -> 2 | H7: Open | BU7: Debug
D8: Approve | E8: 45973 | F8: 45974 | G8: =+F8-E8+1 -> 2 | H8: Open | BW8: Approve
C9: SMT S12 line | D9: HDMI press machine transfer | E9: 45966 | F9: 45971 | G9: =+F9-E9 -> 5 | H9: On-going | BP9: Delivery
D10: Line setup (HDMI press) | E10: 45972 | F10: 45973 | G10: =+F10-E10+1 -> 2 | H10: Open | BV10: Set up
D11: Line debug and qualification | E11: 45973 | F11: 45978 | G11: =+F11-E11 -> 5 | H11: Open | BW11: Debug
D12: Approve | E12: 45979 | F12: 45979 | G12: =+F12-E12+1 -> 1 | H12: Open | CC12: Approve
C13: SMT S1 line | D13: HDMI press machine transfer | E13: 45966 | F13: 45971 | G13: =+F13-E13 -> 5 | H13: On-going | BP13: Delivery
D14: Line setup (HDMI press) | E14: 45972 | F14: 45973 | G14: =+F14-E14+1 -> 2 | H14: Open | BV14: Set up
D15: Line debug and qualification | E15: 45976 | F15: 45981 | G15: =+F15-E15 -> 5 | H15: Open | BZ15: Debug
D16: Approve | E16: 45982 | F16: 45983 | G16: =+F16-E16+1 -> 2 | H16: Open | CF16: Approve
A17: 2 | B17: BFT testing | C17: Test Line #1 Auto BFT (Reuse from DVT) L1 start date: 11/17 | D17: Debug | E17: 45952 | F17: 45955 | G17: =F17-E17 -> 3 | H17: Closed | BB17: Debug
D18: Line qual | E18: 45964 | F18: 45971 | G18: =F18-E18 -> 7 | H18: On-going | BN18: Line qual
D19: Trial run | E19: 45973 | F19: 45973 | G19: =F19-E19+1 -> 1 | H19: Open | BW19: TR
D20: Approve | E20: 45973 | F20: 45974 | G20: =F20-E20+1 -> 2 | H20: Open | BV20: Approve
C21: Test Line #2 Auto BFT (Transfer from LH) L2 start date: 11/20 | D21: Transfer from LH | E21: 45915 | F21: 45927 | G21: =F21-E21 -> 12 | H21: Closed | Q21: Line transfer from LH
D22: Fixture modification | E22: 45922 | F22: 45955 | G22: =F22-E22 -> 33 | H22: Closed | X22: PR,PO | AE22: Fabrication
D23: Line setup & Debug | E23: 45957 | F23: 45969 | G23: =F23-E23 -> 12 | H23: On-going | BG23: Setup & debug
D24: Line qual | E24: 45971 | F24: 45975 | G24: =F24-E24+1 -> 5 | H24: Open | BU24: Line qual
D25: Trial run | E25: 45978 | F25: 45978 | G25: =F25-E25+1 -> 1 | H25: Open | CB25: TR
D26: Approve | E26: 45976 | F26: 45978 | G26: =F26-E26 -> 2 | H26: Open | BZ26: Approve
C27: Test Line #3 Auto BFT L3 start date: 11/24 | D27: Fixture modification | E27: 45922 | F27: 45959 | G27: =F27-E27 -> 37 | H27: Closed | X27: PR,PO | AE27: Fabrication
D28: Line setup & Debug | E28: 45960 | F28: 45973 | G28: =F28-E28 -> 13 | H28: On-going | BJ28: Setup & debug
D29: Line qual | E29: 45974 | F29: 45979 | G29: =F29-E29 -> 5 | H29: Open | BX29: Line qual
D30: Trial run | E30: 45981 | F30: 45981 | G30: =F30-E30+1 -> 1 | H30: Open | CE30: TR
D31: Approve | E31: 45980 | F31: 45981 | G31: =F31-E31+1 -> 2 | H31: Open | CD31: Approve
C32: Test Line #4 Auto BFT L4 start date: 11/27 | D32: Fixture modification | E32: 45922 | F32: 45962 | G32: =F32-E32 -> 40 | H32: On-going | X32: PR,PO | AE32: Fabrication
D33: Line setup & Debug | E33: 45964 | F33: 45976 | G33: =F33-E33 -> 12 | H33: Open | BN33: Setup & debug
D34: Line qual | E34: 45978 | F34: 45982 | G34: =F34-E34+1 -> 5 | H34: Open | CB34: Line qual
D35: Trial run | E35: 45985 | F35: 45985 | G35: =F35-E35+1 -> 1 | H35: Open | CI35: TR
D36: Approve | E36: 45983 | F36: 45985 | G36: =F36-E36 -> 2 | H36: Open | CG36: Approve
A37: 3 | B37: Auto Panel assembly | C37: ASSY AUTO: Panel Line*1 (DVT line) | D37: Line setup & Debug | E37: 45957 | F37: 45962 | G37: =+F37-E37 -> 5 | H37: Closed | BG37: Set up
D38: Line qual | E38: 45964 | F38: 45971 | G38: =+F38-E38 -> 7 | H38: On-going | BL38: Line qual
D39: Trial run | E39: 45973 | F39: 45973 | G39: =+F39-E39+1 -> 1 | H39: Open | BW39: TR
D40: Approve | E40: 45974 | F40: 45975 | G40: =+F40-E40+1 -> 2 | H40: Open | BV40: Approve
C41: ASSY AUTO: Panel Line*2 (retrofit from Sheldon VN) Glue dispensing machine arrived on 11/6 & set up from 11/7 | D41: Line setup & Debug | E41: 45968 | F41: 45972 | G41: =+F41-E41 -> 4 | H41: On-going | BR41: Set up & debug
...

Sheet Line Qual Summary
A1: Calypso VN PVT SMT and FATP Line Setup and Qualification Schedule
A2: Station | B2: Qualifiation item | C2: Oct | AH2: Nov | BL2: Dec
C3: 1 | D3: 2 | E3: 3 | F3: 4 | G3: 5 | H3: 6 | I3: 7 | J3: 8 | K3: 9 | L3: 10 | M3: 11 | N3: 12 | O3: 13 | P3: 14 | Q3: 15 | R3: 16 | S3: 17 | T3: 18 | U3: 19 | V3: 20 | W3: 21 | X3: 22 | Y3: 23 | Z3: 24 | AA3: 25 | AB3: 26 | AC3: 27 | AD3: 28 | AE3: 29 | AF3: 30 | AG3: 31 | AH3: 1 | AI3: 2 | AJ3: 3 | AK3: 4 | AL3: 5 | AM3: 6 | AN3: 7 | AO3: 8 | AP3: 9 | AQ3: 10 | AR3: 11 | AS3: 12 | AT3: 13 | AU3: 14 | AV3: 15 | AW3: 16 | AX3: 17 | AY3: 18 | AZ3: 19 | BA3: 20 | BB3: 21 | BC3: 22 | BD3: 23 | BE3: 24 | BF3: 25 | BG3: 26 | BH3: 27 | BI3: 28 | BJ3: 29 | BK3: 30 | BL3: 1 | BM3: 2 | BN3: 3 | BO3: 4 | BP3: 5 | BQ3: 6 | BR3: 7 | BS3: 8 | BT3: 9 | BU3: 10 | BV3: 11 | BW3: 12 | BX3: 13 | BY3: 14 | BZ3: 15 | CA3: 16 | CB3: 17 | CC3: 18 | CD3: 19 | CE3: 20 | CF3: 21 | CG3: 22 | CH3: 23 | CI3: 24 | CJ3: 25 | CK3: 26 | CL3: 27 | CM3: 28 | CN3: 29 | CO3: 30 | CP3: 31
A4: SMT | B4: SMT Line qualification (CPK+GRR) S2 | AN4: Setup | AQ4: Debug | AS4: Customer approval | AU4: ※PVT
B5: SMT Line qualification (CPK+GRR) S12 | AR5: Setup | AS5: Debug | AX5: Customer approval | AZ5: ※PVT
B6: SMT Line qualification (CPK+GRR) S1 | AR6: Setup | AV6: Debug | BB6: Customer approval | BE6: ※PVT
A7: Test Station BFT Line1 BF T * 4 | B7: Strain Gauge + GRR + Correlation | X7: Debug | AJ7: Line qualificaiton (Strain Gauge + GRR + Correlation) | AR7: Customer approval | AX7: ※PVT
A8: Test Station BFT Line2 BFT*4 | B8: Strain Gauge + GRR + Correlation | AC8: Set up & debug | AQ8: Line qualificaiton (Strain Gauge + GRR + Correlation) | AV8: Customer approval | BA8: ※PVT
A9: Test Station BFT Line3 BFT*4 | B9: Strain Gauge + GRR + Correlation | AF9: Set up & debug | AT9: Line qualificaiton (Strain Gauge + GRR + Correlation) | AZ9: Customer approval | BE9: ※PVT
A10: Test Station BFT Line4 BFT*4 | B10: Strain Gauge + GRR + Correlation | AJ10: Set up & debug | AX10: Line qualificaiton (Strain Gauge + GRR + Correlation) | BC10: Customer approval | BH10: ※PVT
A11: ASSY AUTO: Panel Line*4 | B11: Auto Fungible 1.0 Assy line1 (POR line) | AC11: Setup ready | AJ11: Line qualificaiton (Force CPK + Paper test+ Strain gauge | AS11: Trial run | AT11: Customer approval | AV11: FAI build | AX11: ※PVT
B12: Auto Fungible 1.0 Assy line 2 | AN12: Setup ready | AS12: Line qualificaiton (Force CPK + Paper test+ Strain gauge) | AX12: Customer approval | BA12: ※PVT
B13: Auto Fungible 1.0 Assy line 3 | V13: Line transfer from LH | AQ13: Setup ready | AV13: Line qualificaiton (Force CPK + Paper test+ Strain gauge) | BA13: Customer approval | BE13: ※PVT
B14: Auto Fungible 1.0 Assy line 4 | V14: Line transfer from LH | AS14: Setup ready | AX14: Line qualificaiton (Force CPK + Paper test+ Strain gauge) | BE14: Customer approval | BH14: ※PVT
A15: ASSY AUTO: Housing*2 | B15: Auto Fungible 2.0 Assy line1 (POR line) | AC15: Setup ready | AJ15: Line qualificaiton (Force Cpk+Paper test+ Strain gauge) | AR15: Customer approval | AX15: ※PVT
B16: Auto Fungible 2.0 Assy line2 (Retrofit Callie VN HSG line) | AQ16: Set up & debug | AX16: Line qualification | BB16: Customer approval | BE16: ※PVT
A17: Test Station FTS Line1 FTS * 2 Cell (12+12) | B17: GRR + Correlation | X17: Debug | AK17: Line qualificaiton (GRR + Correlation) | AS17: Customer approval | AX17: ※PVT
A18: Test Station FPS Line1 FPS * 4 | B18: Loop Test | X18: Debug | AK18: Line qualificaiton (GRR + Correlation) | AS18: Customer approval | AX18: ※PVT
A19: Test Station FTS Line2 FTS * 2Cell (12+12) | B19: GRR + Correlation | AD19: Set up & debug | AQ19: Line qualificaiton (GRR + Correlation) | AX19: Customer approval | BA19: ※PVT
A20: Test Station FPS Line2 FPS*4 | B20: Loop Test | AD20: Set up & debug | AQ20: Line qualificaiton (GRR + Correlation) | AX20: Customer approval | BA20: ※PVT
A21: Test Station FTS Line3 FTS*2Cell (12+12) | B21: GRR + Correlation | AK21: Set up & debug | AU21: Line qualificaiton (GRR + Correlation) | BA21: Customer approval | BE21: ※PVT
A22: Test Station FPS Line3 FPS*4 | B22: Loop Test | AK22: Set up & debug | AU22: Line qualificaiton (GRR + Correlation) | BA22: Customer approval | BE22: ※PVT
A23: Test Station FTS Line4 FTS*2Cell (12+12) | B23: GRR + Correlation | AO23: Set up & debug | AY23: Line qualificaiton (GRR + Correlation) | BE23: Customer approval | BH23: ※PVT
A24: Test Station FPS Line4 FPS*4 | B24: Loop Test | AO24: Set up & debug | AY24: Line qualificaiton (GRR + Correlation) | BE24: Customer approval | BH24: ※PVT
A25: Pack out line #1 Manual | B25: VI Station (Fault injection) | AJ25: Set up & debug | AR25: Line qualificaiton & Trial run | AU25: Customer approval | AZ25: ※PVT
A26: Pack out line #2 Manual | B26: VI Station (Fault injection) | AM26: Set up & debug | AU26: Line qualificaiton & Trial run | AY26: Customer approval | BB26: ※PVT
A27: Pack out line #3 Manual | B27: VI Station (Fault injection) | AR27: Set up & debug | AZ27: Line qualificaiton & Trial run | BC27: Customer approval | BG27: ※PVT
A28: Pack out line #4 Manual | B28: VI Station (Fault injection) | AU28: Set up & debug | BC28: Line qualificaiton & Trial run | BG28: Customer approval | BJ28: ※PVT
A29: Pack out line #5 Manual | B29: VI Station (Fault injection) | AU29: Set up & debug | BC29: Line qualificaiton & Trial run | BG29: Customer approval | BM29: ※PVT
A30: Pack out line #1 Auto (Ramp after OK2S) | B30: Fault injection | CA30: Line setup & debug | CH30: Line qualificaiton (Fault injection) | CN30: Trial run | CO30: Customer approval

Sheet OBA Readiness 
B1: OBA Readiness Review for PVT
B2: No. | C2: Contents | D2: PVT | F2: Remark
C3: Contents | D3: Status | E3: Due date | F3: Remark
B4: 1 | C4: Product build Milestone | D4: Closed | E4: 45940 | F4: Follow up OPM Build Matrix
B5: 2 | C5: Escalation List | D5: Closed | E5: 45919
B6: 3 | C6: OBA Facility Check List | D6: on-going | E6: 45971 | F6: Add 3 Shielding rooms with TV and fixture to Calypso: - Onhand 3 Shielding rooms - Already Moved 3 Shielding rooms to Calypso, on-going to setup electric, network, TV. - 20pcs
B7: 4 | C7: OBA Layout | D7: Closed | E7: 45971 | F7: Set up shielding room and setup to Calypso
B8: 5 | C8: OBA Operator Training Plan | D8: on-going | E8: 45976 | F8: Start from 11/08, complete by 11/15
B9: 6 | C9: SIP - based on TCD | D9: Closed | E9: 45957 | F9: Update SIP based on new OBA TCD provide by DQM.
B10: 7 | C10: OBA Capacity--OBA | D10: Closed | E10: 45940
B11: 8 | C11: CET Plan | D11: Closed | E11: 45971
B12: 9 | C12: Weekly Review action item list | D12: on-going | E12: Daily
B13: 10 | C13: OBA PVT Regression test | D13: Closed | E13: 45962 | F13: GMC regression test user image 19
B16: Summary:
B17: No risk

Sheet IQC Readiness
B1: Calypso IQC Readiness Summary
B2: No. | C2: Items | D2: CM/AMZ DRI | E2: Due date | F2: Status
B3: 1 | C3: MMIL(Material Major Issue list) through build | D3: Tongzhang/Evan | E3: 45948 | F3: Closed | G3: All material issues have been closed
B4: 2 | C4: Team list | D4: Tongzhang/Evan | E4: 45665 | F4: Closed
B5: 3 | C5: Project schedule | D5: Tongzhang/Evan | E5: 45665 | F5: Closed
B6: 4 | C6: Key part list&material ETA&IQC plan | D6: Tongzhang/Evan | E6: 45665 | F6: Closed
B7: 5 | C7: Key parts vendors OQC/IQC alignment | D7: Tongzhang/Evan | E7: 45683 | F7: Closed
B8: 6 | C8: SIP/MSOP readiness | D8: Tongzhang/Evan | E8: 45885 | F8: Closed
B9: 7 | C9: Reference/Limit/Golden/Construction samples list | D9: Tongzhang/Evan | E9: 45948 | F9: Closed | G9: PVT golden and limit sample ID has been signed
B10: 8 | C10: Equipment/Fixture readiness | D10: Tongzhang/Evan | E10: 45665 | F10: Closed
B11: 9 | C11: IQC inspector list/training | D11: Tongzhang/Evan | E11: 45665 | F11: Closed
B12: 10 | C12: Measurement&Inspection Qualification(GRR/ARR & Correlation) | D12: Tongzhang/Evan | E12: 45971 | F12: Ongoing | G12: IQC need to do ARR follow limit sample
B13: 11 | C13: Supplier audit plan(For key Non-A parts) | D13: Tongzhang/Evan | E13: 45665 | F13: Closed
B14: 12 | C14: SI arrange plan(For key ME parts) | D14: Tongzhang/Evan | E14: 45971 | F14: Ongoing | G14: Arrange VN IQC team go to VN N.W.E SI.
B15: 13 | C15: Material vendor on-site support plan | D15: Tongzhang/Evan | E15: 45665 | F15: Closed
B16: 14 | C16: Material vendor sorting area & capacity | D16: Tongzhang/Evan | E16: 45665 | F16: Closed

Sheet DGL pre-launch
A1: Calypso | B1: Pre-Lauch Checking List
A2: OK to ship day: | B2: 45999
A3: Planned first ship day: | B3: 46001
A5: *CM needs to consult with CMM on which column (D or E) when working on new program checklist
G6: Updated by CM
A7: Category | B7: Item | C7: Start Date | D7: Device PIC | E7: Remark | F7: Parking lot | G7: Weekly Status | H7: Weekly Highlights
A8: CM Checking List | B8: Vendor Code /Customer Code | C8: 2 month before OK2S | D8: OEM | G8: Completed
B9: DTMS configuration setup checking for Manual ASIN weights and DIMS, Program configuration, Vendor configuration | C9: 4 weeks before ok2ship | D9: N/A to device | G9: N/A | H9: Not required for Devices
B10: SSCC pre-fix apply with GS1(new CM) | C10: 2 months before OK2ship | D10: DGL NPI | G10: Completed
B11: Ring: SSCC requirement with complaince checking | C11: 4 weeks before ok2ship | G11: N/A | H11: Not required for Devices
B12: Check whether Leather Contained or not, if yes, check Leather source with vendor, get prepared to issue Declaration of Leather source for shipment to India and Italy, get prepared to issue COO for India. | C12: 2 month before OK2Ship | D12: MM | G12: N/A | H12: No leather
B13: Battery Documents (UN38.3, MSDS, 3M Drop Test) & Device level Certificate(Safe Transportation Certificate), DG license & process (if any) Readiness and send to LSPs for pre-check, details refer to SOP 4.3 attachment | C13: 1 month before OK2Ship | D13: DGL CMM | G13: Completed | H13: Have enough MSDS, Test report. No requirement for 3M Drop test.
B14: For Magnet document (MSDS / Magnet testing report/Safe Transportation Certificate) | C14: 1 month before OK2S | D14: DGL CMM | G14: N/A | H14: Non-magnetic Dry battery only
B15: CM logistics are required to check the new project whether include below sensitive materials (refer to a sensitive materials in file 4.3 master check list) which may impact the product transportation and need prepare the related certificate to forwarder to check for booking acceptance in advance. | C15: 1 month before OK2S | D15: CM | E15: Sensitive materials 含液体的产品 - Liquid 含磁的产品 - Magnetism 含电池的产品 – battery 含有马达的电器 – Motor 含有粉末 – Powder 化学物质 - Chemicals 含爆炸易燃 - the inflammables and explosives | G15: Completed | H15: Dry battery only
B16: BOM & Customs registration Readiness | C16: 1 week before OK2SHIP | D16: CM | G16: In progress | H16: Due date: 28-Nov-2025
B17: Shipment in/to CN FCs (if any) Process Review | C17: 2 month before okship | D17: DGL CMM | G17: In progress | H17: Due date: 10-Nov-2025
B18: Pallet type Matrix Check in Agile | C18: 1 month before okship | D18: DGL NPI | G18: Completed | H18: Follow Pallet Matrix 05-000818 ver 28
B19: Vendor Central PO Receiving | C19: 1 month before okship | D19: FP | G19: Completed | H19: PO received
B20: HTS code & PD readiness | C20: 1 month before okship | D20: Global Trade Compliance | G20: Completed
B21: Check ECCN for shipment to IC2S/ICA2 (MX, AU, BR OFFLINE) | C21: 1 month before okship | D21: Global Trade Compliance | G21: In progress | H21: Due date: 10-Nov-2025
B22: Authorization Letter / IPR registration (if applicable) | C22: 1 month before okship | D22: Global Trade Compliance | G22: N/A | H22: In Vietnam: inapplicable
B23: Booking for the first shipment | C23: per timeline of different ship mode | D23: DGL CMM | G23: Not start | H23: Due date: 26-Nov-2025
B24: Check internal counterpart whether FCC certificate was granted for US shipments. | C24: 1 month before okship | D24: DGL NPI | G24: In progress | H24: Due date: 10-Nov-2025
B25: Check internal counterpart whether ISED certificate was granted for Canada shipments. | C25: 1 month before ok2ship | D25: DGL NPI | G25: In progress | H25: Due date: 10-Nov-2025
B26: Check internal counterpart whether WPC import license and AAR filing ready for India shipments | C26: 1 month before ok2ship | D26: DGL NPI | G26: In progress | H26: Due date: 10-Nov-2025
B27: Ring: Pallet packing reliability testing passing confirmation: viabration reliability testing, static storage simulation testing, truck loading/unloading simulation testing, and etc. | C27: 1 month before ok2ship | D27: N/A to device | G27: N/A | H27: No requirement for Devices
B28: Ring: Ring carton and pallet label guide confirmation: please refer to the doc of "5-026425-11_Ring_PACK_LabelGuide_v11a" | C28: 1 month before ok2ship | D28: N/A to device | G28: N/A | H28: No requirement for Devices
B29: Ring: Adile BOM readiness checking | C29: 1 month before ok2ship | D29: N/A to device | G29: N/A | H29: No requirement for Devices
B30: Product packing information confirmation: (1) carton and pallet packing design frozen confirmation, (2) Carton and pallet packing SOP confirmation, (3) pallet usage matrix confirmation, (4) all kinds of length/wedith/height dimension and weight information confirmation, (5) carton and pallet SSCC bar code design confirmation, (6) double pallet stacking design confirmation. (7) Ring - Retail box design drawing passed | C30: 4 weeks before ok2ship | D30: N/A to device | G30: N/A | H30: No requirement for Devices
B31: Required documents for shipping: 1. MSDS documents for dry batteries 2. Test Reports for dry batteries 3. Letters of Indemnity confirming that our batteries comply with the rules for transportation of dangerous goods | C31: per shipment | D31: OEM | E31: Already on hand | G31: Completed
A33: Completed
A34: In progress
A35: Not start
A36: N/A

Sheet OP Trainning plan
B2: Stage | C2: Process | D2: Training contents | E2: Line | F2: OP qty | G2: OP Hiring | H2: Ops On Board | I2: Training date | J2: OP Training Report | K2: Online | L2: Status
B3: PVT | C3: SMT | D3: a. ESD/ occupational safety b.Feed PCB board c.Machine operation d.Abnormal handing e.Form check f.VI | E3: Line S2 | F3: 8 | G3: / | H3: / | I3: 2025/11/05 - 2025/11/10 | J3: 45973 | K3: 45975 | L3: Line is allocating for other projects
E4: Line S12 | F4: 8 | G4: / | H4: / | I4: 2025/11/11 - 2025/11/16 | J4: 45978 | K4: 45980 | L4: Line is allocating for other projects
E5: Line S1 | F5: 8 | G5: / | H5: / | I5: 2025/11/15- 2025/11/19 | J5: 45982 | K5: 45985 | L5: Line is allocating for other projects
C6: BFT | D6: a. ESD/ occupational safety b. Feed PCBA board c. Machine operation d. Abnormal handing e. Form check f. VI | E6: Line 1 ~ Line 4 | F6: 1 | G6: / | H6: / | I6: 2025/11/08-2025/11/11 | J6: 45973 | K6: 45975 | L6: Follow SMT line start date
C7: Routing | D7: PCBA routing | E7: Routing machine | F7: / | G7: / | H7: / | I7: 2025/11/11-2025/11/14 | J7: 45975 | K7: 45978
C8: Assembly & Test | D8: a. ESD/ occupational safety b. Fixture operation c. Abnormal handing d. Form check e. VI | E8: Line1 | F8: 7 | G8: / | H8: / | I8: 2025/11/11-2025/11/14 | J8: 45975 | K8: 45978
E9: Line2 | F9: 7 | G9: / | H9: / | I9: 2025/11/13-2025/11/17 | J9: 45979 | K9: 45981
E10: Line 3 | F10: 7 | G10: / | H10: / | I10: 2025/11/17-2025/11/20 | J10: 45982 | K10: 45985
E11: Line 4 | F11: 7 | G11: / | H11: / | I11: 2025/11/20-2025/11/24 | J11: 45986 | K11: 45988
C12: PACKING | D12: a.SOP learning b.Abnormal handing c.Form check d.VI | E12: Manual line 1 | F12: 13 | G12: / | H12: / | I12: 2025/11/11-2025/11/14 | J12: 45976 | K12: 45979
E13: Manual line 2 | F13: 13 | G13: / | H13: / | I13: 2025/11/13-2025/11/17 | J13: 45979 | K13: 45981
E14: Manual line 3 | F14: 13 | G14: / | H14: / | I14: 2025/11/18-2025/11/21 | J14: 45983 | K14: 45986
E15: Manual line 4 | F15: 13 | G15: / | H15: / | I15: 2025/11/21-2025/11/25 | J15: 45987 | K15: 45989
E16: Manual line 5 | G16: / | H16: / | I16: 2025/11/24-2025/11/27 | J16: 45989 | K16: 45992

Sheet VN layout
A2: 1. SMT LAYOUT
A40: 2. FATP LAYOUT
A41: Remark: Move packing POR line next to left over 4 packing lines after DVT for PVT

Sheet Reports for OK2S
A1: PVT Data cut off:
A2: No | B2: Type of report | C2: Passing criteria | D2: Test requirement | E2: Submit Time | F2: ETC/Approval | G2: CNT DRI | H2: AMZ DRI | I2: Status | J2: Remark | K2: File
A3: 1 | B3: ORT | D3: ORT pick up plan 10pcs PCBA+100pcs device | E3: Sample pick up from 3/27, test time last 2 weeks | G3: Quinn | H3: JINJUN | J3: PCBA pick up date: 3/27 (10pcs) Line 1# day shift pick up date: 4/1 50pcs Line 1# night shift pick up date: 4/1 50pcs
A4: 2 | B4: IQC | D4: will daily update in the PVT open/close meeting | E4: daily tracking and update | F4: - | G4: PM Wanda | H4: FMQM Cotton
A5: 3 | B5: SMT | D5: will daily update in the PVT open/close meeting | E5: daily tracking and update | F5: - | G5: PQE Estellle | H5: SMT STM Dong
A6: 4 | B6: FATP | D6: will daily update in the PVT open/close meeting | E6: daily tracking and update | F6: - | G6: PQE Estellle | H6: FATP STM Duke
A7: 5 | B7: 53- FAI report | D7: material/PN are correct | E7: 45754 | F7: 45755 | G7: PKG RD Meredith | H7: STM Duke / DQM Phil
A8: 6 | B8: cross section | E8: 4/8~4/22 | F8: 45771 | G8: ME Yandong | H8: SMT STM Dong
A9: 7 | B9: OP training | D9: OP qualified for production | F9: 45752 | G9: PM Wanda | H9: SMT STM Dong/FATP STM Duke
A10: 8 | B10: CET Test | D10: *CET plan in PVT: Callie : 6 pallets | E10: Estimate CET test time: 12days - Pre-Seal test before: 7days (4/7-4/15) - Packout 6 pallets : 1 day (4/16) - CET test: 1 day (4/17) - Post CET: 1 days (4/18). - Make report : 2 day(Post CET&Aging report) (4/22) | F10: 45770 | G10: PQE Estellle | H10: DQM Phil Chen | I10: On-going | J10: Estimate time CET pick up start from 4/9
A11: 9 | B11: OBA | D11: Update new sampling rate check in PVT: 1. Pre-seal (devices): 663 first pcs with new line/shift, then switch to 3.4% (line UPH 498). 2.1 OBA3(Box-Accessories) : 438 first pcs with new line/shift, then switch to 4% for Manual packing line (UPH 411). 2.2 OBA take 25 sets of accessories (Adapter, HDMI cable, Micro USB cable will be checked function at the beginning of every working day. 3. Post-seal: 6 pcs/line/shift (3pcs/line/shift to test without Aquila, 3pcs/line/shift to test Aquila only) | E11: Line1(UPH 498) start on 2025/4/7 Line2(UPH 498) start on 2025/4/10 | F11: OK2S 2025/4/30 | G11: PQE Estellle | H11: DQM Phil Chen | I11: On-going
A12: 10 | B12: Teardown audit | D12: Callie : 1pc | E12: 45757 | F12: 45758 | G12: PQE Estellle | H12: DQM Phil Chen | I12: On-going | J12: Estimate time

Sheet Ramp up plan by line
R1: 12500
B2: Calypso- PVT/MP SMT input Plan | Z2: Cut off data | AA2: Submit reports | AB2: Review reports | AG2: OK2Ship | AI2: FFS
D3: Sun | E3: Mon | F3: Tue | G3: Wed | H3: Thu | I3: Fri | J3: Sat | K3: Sun | L3: Mon | M3: Tue | N3: Wed | O3: Thu | P3: Fri | Q3: Sat | R3: Sun | S3: Mon | T3: Tue | U3: Wed | V3: Thu | W3: Fri | X3: Sat | Y3: Sun | Z3: Mon | AA3: Tue | AB3: Wed | AC3: Thu | AD3: Fri | AE3: Sat | AF3: Sun | AG3: Mon | AH3: Tue | AI3: Wed | AJ3: Thu | AK3: Fri | AL3: Sat
D4: 45970 | E4: 45971 | F4: 45972 | G4: 45973 | H4: 45974 | I4: 45975 | J4: 45976 | K4: 45977 | L4: 45978 | M4: 45979 | N4: 45980 | O4: 45981 | P4: 45982 | Q4: 45983 | R4: 45984 | S4: 45985 | T4: 45986 | U4: 45987 | V4: 45988 | W4: 45989 | X4: 45990 | Y4: 45991 | Z4: 45992 | AA4: 45993 | AB4: 45994 | AC4: 45995 | AD4: 45996 | AE4: 45997 | AF4: 45998 | AG4: 45999 | AH4: 46000 | AI4: 46001 | AJ4: 46002 | AK4: 46003 | AL4: 46004
B5: SMT S2 (6H2G) | I5: 204 | J5: 1200 | L5: 2400 | M5: 3600 | N5: 4800 | O5: 6000 | P5: 7200 | Q5: 8400 | S5: 9600 | T5: 10800 | U5: 12000 | V5: 12000 | W5: 12000 | X5: 12000 | Z5: 12000 | AA5: 12000 | AB5: 12000 | AC5: 12000 | AD5: 12000 | AE5: 12000 | AG5: 12000 | AH5: 12000 | AI5: 12000 | AJ5: 12000 | AK5: 12000 | AL5: 12000
B6: SMT S12 (5H2G) | N6: 204 | O6: 1200 | P6: 2400 | Q6: 3600 | S6: 4800 | T6: 6000 | U6: 7200 | V6: 8400 | W6: 9600 | X6: 10800 | Z6: 12000 | AA6: 12000 | AB6: 12000 | AC6: 12000 | AD6: 12000 | AE6: 12000 | AG6: 12000 | AH6: 12000 | AI6: 12000 | AJ6: 12000 | AK6: 12000 | AL6: 12000
B7: SMT S1 (6H2G) | S7: 204 | T7: 1200 | U7: 2400 | V7: 3600 | W7: 4800 | X7: 6000 | Z7: 7200 | AA7: 8400 | AB7: 9600 | AC7: 10800 | AD7: 12000 | AE7: 12000 | AG7: 12000 | AH7: 12000 | AI7: 12000 | AJ7: 12000 | AK7: 12000 | AL7: 12000
B8: Daily SMT capacity | H8: =SUM(H5:H7) -> 0 | I8: =SUM(I5:I7) -> 204 | J8: =SUM(J5:J7) -> 1200 | K8: =SUM(K5:K7) -> 0 | L8: =SUM(L5:L7) -> 2400 | M8: =SUM(M5:M7) -> 3600 | N8: =SUM(N5:N7) -> 5004 | O8: =SUM(O5:O7) -> 7200 | ... AL8: =SUM(AL5:AL7) -> 36000
B9: CUM SMT capacity | H9: =G9+H8 -> 0 | I9: =H9+I8 -> 204 | J9: =I9+J8 -> 1404 | K9: =J9+K8 -> 1404 | L9: =K9+L8 -> 3804 | M9: =L9+M8 -> 7404 | N9: =M9+N8 -> 12408 | O9: =N9+O8 -> 19608 | ... AL9: =AK9+AL8 -> 594612
B11: Calypso- PVT/MP FATP input Plan | Z11: Cut off data | AA11: Submit reports | AB11: Review reports | AG11: OK2Ship | AI11: FFS
C12: Shift | D12: Sun | E12: Mon | F12: Tue | G12: Wed | H12: Thu | I12: Fri | J12: Sat | K12: Sun | L12: Mon | M12: Tue | N12: Wed | O12: Thu | P12: Fri | Q12: Sat | R12: Sun | S12: Mon | T12: Tue | U12: Wed | V12: Thu | W12: Fri | X12: Sat | Y12: Sun | Z12: Mon | AA12: Tue | AB12: Wed | AC12: Thu | AD12: Fri | AE12: Sat | AF12: Sun | AG12: Mon | AH12: Tue | AI12: Wed | AJ12: Thu | AK12: Fri | AL12: Sat
D13: 45970 | E13: 45971 | F13: 45972 | G13: 45973 | H13: 45974 | I13: 45975 | J13: 45976 | K13: 45977 | L13: 45978 | M13: 45979 | N13: 45980 | O13: 45981 | P13: 45982 | Q13: 45983 | R13: 45984 | S13: 45985 | T13: 45986 | U13: 45987 | V13: 45988 | W13: 45989 | X13: 45990 | Y13: 45991 | Z13: 45992 | AA13: 45993 | AB13: 45994 | AC13: 45995 | AD13: 45996 | AE13: 45997 | AF13: 45998 | AG13: 45999 | AH13: 46000 | AI13: 46001 | AJ13: 46002 | AK13: 46003 | AL13: 46004
B14: Fungible 1.0*UPH*498-Line 1 | C14: DS | G14: 60 | J14: 24 | L14: =INT(524*9.25*L29*99.5%) -> 723 | M14: Yield review | N14: =INT(524*9.25*N29*99.5%) -> 964 | O14: =INT(524*9.25*O29*99.5%) -> 1446 | P14: =INT(524*9.25*P29*99.5%) -> 1929 | Q14: =INT(524*9.25*Q29*99.5%) -> 2411 | R14: =INT(524*9.25*R29*99.5%) -> 0 | S14: =INT(524*9.25*S29*99.5%) -> 2893 | T14: =INT(524*9.25*T29*99.5%) -> 3375 | U14: =INT(524*9.25*U29*99.5%) -> 3858 | ... AL14: =INT(524*9.25*AL29*99.5%) -> 4581
C15: NS | M15: =INT(524*8.5*M30*99.5%) -> 664 | N15: Yield review | O15: =INT(524*8.5*O30*99.5%) -> 886 | P15: =INT(524*8.5*P30*99.5%) -> 1329 | Q15: =INT(524*8.5*Q30*99.5%) -> 1772 | R15: =INT(524*8.5*R30*99.5%) -> 0 | S15: =INT(524*8.5*S30*99.5%) -> 2215 | T15: =INT(524*8.5*T30*99.5%) -> 2659 | U15: =INT(524*8.5*U30*99.5%) -> 3102 | V15: =INT(524*8.5*V30*99.5%) -> 3545 | ... AL15: =INT(524*8.5*AL30*99.5%) -> 4210
B16: Fungible 1.0*UPH*498-Line 2 | C16: DS | L16: 60 | O16: =INT(524*9.25*O31*99.5%) -> 723 | P16: Yield review | Q16: =INT(524*9.25*Q31*99.5%) -> 964 | R16: =INT(524*9.25*R31*99.5%) -> 0 | S16: =INT(524*9.25*S31*99.5%) -> 1446 | T16: =INT(524*9.25*T31*99.5%) -> 1929 | U16: =INT(524*9.25*U31*99.5%) -> 2411 | V16: =INT(524*9.25*V31*99.5%) -> 2893 | W16: =INT(524*9.25*W31*99.5%) -> 3375 | X16: =INT(524*9.25*X31*99.5%) -> 3858 | ... AL16: =INT(524*9.25*AL31*99.5%) -> 4581
C17: NS | P17: =INT(524*8.5*P32*99.5%) -> 664 | Q17: Yield review | S17: =INT(524*8.5*S32*99.5%) -> 886 | T17: =INT(524*8.5*T32*99.5%) -> 1329 | U17: =INT(524*8.5*U32*99.5%) -> 1772 | V17: =INT(524*8.5*V32*99.5%) -> 2215 | W17: =INT(524*8.5*W32*99.5%) -> 2659 | X17: =INT(524*8.5*X32*99.5%) -> 3102 | Y17: =INT(524*8.5*Y32*99.5%) -> 0 | Z17: =INT(524*8.5*Z32*99.5%) -> 3545 | ... AL17: =INT(524*8.5*AL32*99.5%) -> 4210
B18: Fungible 1.0*UPH*498-Line 3 | C18: DS | O18: 60 | S18: =INT(524*9.25*S33*99.5%) -> 723 | T18: Yield review | U18: =INT(524*9.25*U33*99.5%) -> 964 | V18: =INT(524*9.25*V33*99.5%) -> 1446 | W18: =INT(524*9.25*W33*99.5%) -> 1929 | X18: =INT(524*9.25*X33*99.5%) -> 2411 | Y18: =INT(524*9.25*Y33*99.5%) -> 0 | Z18: =INT(524*9.25*Z33*99.5%) -> 2893 | AA18: =INT(524*9.25*AA33*99.5%) -> 3375 | AB18: =INT(524*9.25*AB33*99.5%) -> 3858 | ... AL18: =INT(524*9.25*AL33*99.5%) -> 4581
C19: NS | T19: =INT(524*8.5*T34*99.5%) -> 664 | U19: Yield review | V19: =INT(524*8.5*V34*99.5%) -> 886 | W19: =INT(524*8.5*W34*99.5%) -> 1329 | X19: =INT(524*8.5*X34*99.5%) -> 1772 | Y19: =INT(524*8.5*Y34*99.5%) -> 0 | Z19: =INT(524*8.5*Z34*99.5%) -> 2215 | AA19: =INT(524*8.5*AA34*99.5%) -> 2659 | AB19: =INT(524*8.5*AB34*99.5%) -> 3102 | AC19: =INT(524*8.5*AC34*99.5%) -> 3545 | ... AL19: =INT(524*8.5*AL34*99.5%) -> 4210
B20: Fungible 1.0*UPH*498-Line 4 | C20: DS | S20: 60 | V20: =INT(524*9.25*V35*99.5%) -> 723 | W20: Yield review | X20: =INT(524*9.25*X35*99.5%) -> 964 | Y20: =INT(524*9.25*Y35*99.5%) -> 0 | Z20: =INT(524*9.25*Z35*99.5%) -> 1446 | AA20: =INT(524*9.25*AA35*99.5%) -> 1929 | AB20: =INT(524*9.25*AB35*99.5%) -> 2411 | AC20: =INT(524*9.25*AC35*99.5%) -> 2893 | AD20: =INT(524*9.25*AD35*99.5%) -> 3375 | AE20: =INT(524*9.25*AE35*99.5%) -> 3858 | ... AL20: =INT(524*9.25*AL35*99.5%) -> 4581
C21: NS | W21: =INT(524*8.5*W36*99.5%) -> 664 | X21: Yield review | Y21: =INT(524*8.5*Y36) -> 0 | Z21: =INT(524*8.5*Z36*99.5%) -> 886 | AA21: =INT(524*8.5*AA36*99.5%) -> 1329 | AB21: =INT(524*8.5*AB36*99.5%) -> 1772 | AC21: =INT(524*8.5*AC36*99.5%) -> 2215 | AD21: =INT(524*8.5*AD36*99.5%) -> 2659 | AE21: =INT(524*8.5*AE36*99.5%) -> 3102 | AF21: =INT(524*8.5*AF36*99.5%) -> 0 | AG21: =INT(524*8.5*AG36*99.5%) -> 3545 | ... AL21: =INT(524*8.5*AL36*99.5%) -> 4210
C22: Total | G22: =SUM(G14:G21) -> 60 | H22: =SUM(H14:H21) -> 0 | I22: =SUM(I14:I21) -> 0 | J22: =SUM(J14:J21) -> 24 | K22: =SUM(K14:K21) -> 0 | L22: =SUM(L14:L21) -> 783 | M22: =SUM(M14:M21) -> 664 | N22: =SUM(N14:N21) -> 964 | ... AL22: =SUM(AL14:AL21) -> 35164
C23: Cum total | G23: =G22 -> 60 | H23: =G23+H22 -> 60 | I23: =H23+I22 -> 60 | J23: =I23+J22 -> 84 | K23: =J23+K22 -> 84 | L23: =K23+L22 -> 867 | M23: =L23+M22 -> 1531 | N23: =M23+N22 -> 2495 | O23: =N23+O22 -> 5610 | ... AL23: =AK23+AL22 -> 482174
C24: WIP(MLB) | I24: =I9-I23 -> 144 | J24: =J9-J23 -> 1320 | K24: =K9-K23 -> 1320 | L24: =L9-L23 -> 2937 | M24: =M9-M23 -> 5873 | N24: =N9-N23 -> 9913 | O24: =O9-O23 -> 13998 | P24: =P9-P23 -> 19676 | ... AL24: =AL9-AL23 -> 112438
C25: SMT WIP VS Daily demand | I25: =IFERROR((I9-I23)/I22,"") | J25: =IFERROR((J9-J23)/J22,"") -> 55 | K25: =IFERROR((K9-K23)/K22,"") | L25: =IFERROR((L9-L23)/L22,"") -> 3.7509579 | M25: =IFERROR((M9-M23)/M22,"") -> 8.8448795 | N25: =IFERROR((N9-N23)/N22,"") -> 10.283195 | O25: =IFERROR((O9-O23)/O22,"") -> 4.49374 | P25: =IFERROR((P9-P23)/P22,"") -> 5.0168281 | ... AL25: =IFERROR((AL9-AL23)/AL22,"") -> 3.1975316
B27: Efficiency | C27: Plan lines | L27: =ROUNDUP(COUNT(L14:L21)/2,0) -> 1 | M27: =ROUNDUP(COUNT(M14:M21)/2,0) -> 1 | N27: =ROUNDUP(COUNT(N14:N21)/2,0) -> 1 | O27: =ROUNDUP(COUNT(O14:O21)/2,0) -> 2 | P27: =ROUNDUP(COUNT(P14:P21)/2,0) -> 2 | Q27: =ROUNDUP(COUNT(Q14:Q21)/2,0) -> 2 | R27: =ROUNDUP(COUNT(R14:R21)/2,0) -> 2 | S27: =ROUNDUP(COUNT(S14:S21)/2,0) -> 3 | ... X27: =ROUNDUP(COUNT(X14:X21)/2,0) -> 4 | Z27: =ROUNDUP(COUNT(Z14:Z21)/2,0) -> 4 | AA27: =ROUNDUP(COUNT(AA14:AA21)/2,0) -> 4 | AB27: =ROUNDUP(COUNT(AB14:AB21)/2,0) -> 4 | AC27: =ROUNDUP(COUNT(AC14:AC21)/2,0) -> 4 | AD27: =ROUNDUP(COUNT(AD14:AD21)/2,0) -> 4 | AE27: =ROUNDUP(COUNT(AE14:AE21)/2,0) -> 4 | AG27: =ROUNDUP(COUNT(AG14:AG21)/2,0) -> 4 | AH27: =ROUNDUP(COUNT(AH14:AH21)/2,0) -> 4 | AI27: =ROUNDUP(COUNT(AI14:AI21)/2,0) -> 4 | AJ27: =ROUNDUP(COUNT(AJ14:AJ21)/2,0) -> 4 | AK27: =ROUNDUP(COUNT(AK14:AK21)/2,0) -> 4 | AL27: =ROUNDUP(COUNT(AL14:AL21)/2,0) -> 4
C28: Plan shifts | L28: =COUNT(L14:L21) -> 2 | M28: =COUNT(M14:M21) -> 1 | N28: =COUNT(N14:N21) -> 1 | O28: =COUNT(O14:O21) -> 4 | P28: =COUNT(P14:P21) -> 3 | Q28: =COUNT(Q14:Q21) -> 3 | R28: =COUNT(R14:R21) -> 3 | S28: =COUNT(S14:S21) -> 6 | ... X28: =COUNT(X14:X21) -> 7 | Z28: =COUNT(Z14:Z21) -> 8 | AA28: =COUNT(AA14:AA21) -> 8 | AB28: =COUNT(AB14:AB21) -> 8 | AC28: =COUNT(AC14:AC21) -> 8 | AD28: =COUNT(AD14:AD21) -> 8 | AE28: =COUNT(AE14:AE21) -> 8 | AG28: =COUNT(AG14:AG21) -> 8 | AH28: =COUNT(AH14:AH21) -> 8 | AI28: =COUNT(AI14:AI21) -> 8 | AJ28: =COUNT(AJ14:AJ21) -> 8 | AK28: =COUNT(AK14:AK21) -> 8 | AL28: =COUNT(AL14:AL21) -> 8
B29: Fungible 1.0*UPH*498-Line 1 | C29: DS | J29: FAI | L29: 0.15 | M29: Yield review | N29: 0.2 | O29: 0.3 | P29: 0.4 | Q29: 0.5 | S29: 0.6 | T29: 0.7 | U29: 0.8 | V29: 0.85 | W29: 0.9 | X29: 0.95 | Z29: 0.95 | AA29: 0.95 | AB29: 0.95 | AC29: 0.95 | AD29: 0.95 | AE29: 0.95 | AG29: 0.95 | AH29: 0.95 | AI29: 0.95 | AJ29: 0.95 | AK29: 0.95 | AL29: 0.95
C30: NS | M30: 0.15 | N30: Yield review | O30: 0.2 | P30: 0.3 | Q30: 0.4 | S30: 0.5 | T30: 0.6 | U30: 0.7 | V30: 0.8 | W30: 0.85 | X30: 0.9 | Z30: 0.95 | AA30: 0.95 | AB30: 0.95 | AC30: 0.95 | AD30: 0.95 | AE30: 0.95 | AG30: 0.95 | AH30: 0.95 | AI30: 0.95 | AJ30: 0.95 | AK30: 0.95 | AL30: 0.95
B31: Fungible 1.0*UPH*498-Line 2 | C31: DS | O31: 0.15 | P31: Yield review | Q31: 0.2 | S31: 0.3 | T31: 0.4 | U31: 0.5 | V31: 0.6 | W31: 0.7 | X31: 0.8 | Z31: 0.85 | AA31: 0.9 | AB31: 0.95 | AC31: 0.95 | AD31: 0.95 | AE31: 0.95 | AG31: 0.95 | AH31: 0.95 | AI31: 0.95 | AJ31: 0.95 | AK31: 0.95 | AL31: 0.95
C32: NS | P32: 0.15 | Q32: Yield review | S32: 0.2 | T32: 0.3 | U32: 0.4 | V32: 0.5 | W32: 0.6 | X32: 0.7 | Z32: 0.8 | AA32: 0.85 | AB32: 0.9 | AC32: 0.95 | AD32: 0.95 | AE32: 0.95 | AG32: 0.95 | AH32: 0.95 | AI32: 0.95 | AJ32: 0.95 | AK32: 0.95 | AL32: 0.95
B33: Fungible 1.0*UPH*498-Line 3 | C33: DS | S33: 0.15 | T33: Yield review | U33: 0.2 | V33: 0.3 | W33: 0.4 | X33: 0.5 | Z33: 0.6 | AA33: 0.7 | AB33: 0.8 | AC33: 0.85 | AD33: 0.9 | AE33: 0.95 | AG33: 0.95 | AH33: 0.95 | AI33: 0.95 | AJ33: 0.95 | AK33: 0.95 | AL33: 0.95
C34: NS | T34: 0.15 | U34: Yield review | V34: 0.2 | W34: 0.3 | X34: 0.4 | Z34: 0.5 | AA34: 0.6 | AB34: 0.7 | AC34: 0.8 | AD34: 0.85 | AE34: 0.9 | AG34: 0.95 | AH34: 0.95 | AI34: 0.95 | AJ34: 0.95 | AK34: 0.95 | AL34: 0.95
B35: Fungible 1.0*UPH*498-Line 4 | C35: DS | V35: 0.15 | W35: Yield review | X35: 0.2 | Z35: 0.3 | AA35: 0.4 | AB35: 0.5 | AC35: 0.6 | AD35: 0.7 | AE35: 0.8 | AG35: 0.85 | AH35: 0.9 | AI35: 0.95 | AJ35: 0.95 | AK35: 0.95 | AL35: 0.95
C36: NS | W36: 0.15 | X36: Yield review | Z36: 0.2 | AA36: 0.3 | AB36: 0.4 | AC36: 0.5 | AD36: 0.6 | AE36: 0.7 | AG36: 0.8 | AH36: 0.85 | AI36: 0.9 | AJ36: 0.95 | AK36: 0.95 | AL36: 0.95
C37: Working hour | L37: =9.5*L28 -> 19 | M37: =9.5*M28 -> 9.5 | N37: =9.5*N28 -> 9.5 | O37: =9.5*O28 -> 38 | P37: =9.5*P28 -> 28.5 | Q37: =9.5*Q28 -> 28.5 | R37: =9.5*R28 -> 28.5 | S37: =9.5*S28 -> 57 | ... AL37: =9.5*AL28 -> 76
B39: Calypso- PVT/MP Packout input Plan | AG39: OK2Ship | AI39: FFS
C40: Shift | D40: Sun | E40: Mon | F40: Tue | G40: Wed | H40: Thu | I40: Fri | J40: Sat | K40: Sun | L40: Mon | M40: Tue | N40: Wed | O40: Thu | P40: Fri | Q40: Sat | R40: Sun | S40: Mon | T40: Tue | U40: Wed | V40: Thu | W40: Fri | X40: Sat | Y40: Sun | Z40: Mon | AA40: Tue | AB40: Wed | AC40: Thu | AD40: Fri | AE40: Sat | AF40: Sun | AG40: Mon | AH40: Tue | AI40: Wed | AJ40: Thu | AK40: Fri | AL40: Sat
D41: 45970 | E41: 45971 | F41: 45972 | G41: 45973 | H41: 45974 | I41: 45975 | J41: 45976 | K41: 45977 | L41: 45978 | M41: 45979 | N41: 45980 | O41: 45981 | P41: 45982 | Q41: 45983 | R41: 45984 | S41: 45985 | T41: 45986 | U41: 45987 | V41: 45988 | W41: 45989 | X41: 45990 | Y41: 45991 | Z41: 45992 | AA41: 45993 | AB41: 45994 | AC41: 45995 | AD41: 45996 | AE41: 45997 | AF41: 45998 | AG41: 45999 | AH41: 46000 | AI41: 46001 | AJ41: 46002 | AK41: 46003 | AL41: 46004
B42: Manual Packing - Line 1 | C42: DS | H42: 12 | M42: 12 | N42: =INT(411*9.25*N56) -> 760 | O42: =INT(411*9.25*O56) -> 1140 | P42: =INT(411*9.25*P56) -> 1520 | Q42: =INT(411*9.25*Q56) -> 1900 | S42: =INT(411*9.25*S56) -> 2281 | T42: =INT(411*9.25*T56) -> 2661 | U42: =INT(411*9.25*U56) -> 3041 | V42: =INT(411*9.25*V56) -> 3231 | W42: =INT(411*9.25*W56) -> 3421 | X42: =INT(411*9.25*X56) -> 3611 | Z42: =INT(411*9.25*Z56) -> 3801 | AA42: =INT(411*9.25*AA56) -> 3801 | AB42: =INT(411*9.25*AB56) -> 3801 | AC42: =INT(411*9.25*AC56) -> 3801 | AD42: =INT(411*9.25*AD56) -> 3801 | AE42: =INT(411*9.25*AE56) -> 3801 | AF42: =INT(411*9.25*AF56) -> 0 | AG42: =INT(411*9.25*AG56) -> 3801 | ... AL42: =INT(411*9.25*AL56) -> 3801
C43: NS | O43: =INT(411*8.5*O57) -> 698 | P43: =INT(411*8.5*P57) -> 1048 | Q43: =INT(411*8.5*Q57) -> 1397 | S43: =INT(411*8.5*S57) -> 1746 | T43: =INT(411*8.5*T57) -> 2096 | U43: =INT(411*8.5*U57) -> 2445 | V43: =INT(411*8.5*V57) -> 2794 | W43: =INT(411*8.5*W57) -> 2969 | X43: =INT(411*8.5*X57) -> 3144 | Z43: =INT(411*8.5*Z57) -> 3318 | AA43: =INT(411*8.5*AA57) -> 3493 | AB43: =INT(411*8.5*AB57) -> 3493 | AC43: =INT(411*8.5*AC57) -> 3493 | AD43: =INT(411*8.5*AD57) -> 3493 | AE43: =INT(411*8.5*AE57) -> 3493 | AF43: =INT(411*8.5*AF57) -> 0 | AG43: =INT(411*8.5*AG57) -> 3493 | ... AL43: =INT(411*8.5*AL57) -> 3493
...

Sheet Calypso FCST
A2: FCST version: 20251024145808
A3: Cum FCST | B3: =X16 -> 3441000
A4: Project | B4: PartNumber | C4: SKU | D4: 45977 | E4: 45984 | F4: 45991 | G4: 45998 | H4: 46005 | I4: 46012 | J4: 46019 | K4: 46026 | L4: 46033 | M4: 46040 | N4: 46047 | O4: 46054 | P4: 46061 | Q4: =+P4+7 -> 46068 | R4: =+Q4+7 -> 46075 | S4: =+R4+7 -> 46082 | T4: =+S4+7 -> 46089 | U4: =+T4+7 -> 46096 | V4: =+U4+7 -> 46103 | W4: =+V4+7 -> 46110 | X4: =+W4+7 -> 46117
A5: Calypso | B5: 53-100275 | C5: US | D5: 9575 | E5: 9017 | F5: 46046 | G5: 63299 | H5: 63408 | I5: 68944 | J5: 49562 | K5: 80453 | L5: 79835 | M5: 63982 | N5: 36103 | O5: 67633 | P5: 54703 | Q5: 0 | R5: 69356 | S5: 44582 | T5: 74435 | U5: 30338 | V5: 118143 | W5: 46780 | X5: 66597
A6: Calypso | B6: 53-100276 | C6: DE,FR,IT,ES | D6: 0 | E6: 9434 | F6: 35812 | G6: 104701 | H6: 106381 | I6: 94788 | J6: 37035 | K6: 45473 | L6: 48658 | M6: 59145 | N6: 85211 | O6: 48096 | P6: 63071 | Q6: 0 | R6: 30940 | S6: 67535 | T6: 29872 | U6: 31127 | V6: 64154 | W6: 37953 | X6: 97123
A7: Calypso | B7: 53-100763 | C7: AU/NZ | D7: 0 | E7: 40000 | F7: 53060 | G7: 0 | H7: 0 | I7: 1093 | J7: 12 | K7: 5281 | L7: 2377 | M7: 2336 | N7: 2502 | O7: 8128 | P7: 6311 | Q7: 0 | R7: 2369 | S7: 3442 | T7: 0 | U7: 5159 | V7: 5265 | W7: 5006 | X7: 2520
A8: Calypso | B8: 53-100764 | C8: JP | D8: 0 | E8: 6240 | F8: 10915 | G8: 20558 | H8: 30048 | I8: 18160 | J8: 12180 | K8: 18428 | L8: 17754 | M8: 21158 | N8: 20766 | O8: 18861 | P8: 16351 | Q8: 0 | R8: 15777 | S8: 91945 | T8: 77176 | U8: 106369 | V8: 24635 | W8: 13601 | X8: 10851
A9: Calypso | B9: 53-100765 | C9: IN | D9: 0 | E9: 0 | F9: 0 | G9: 0 | H9: 0 | I9: 0 | J9: 0 | K9: 0 | L9: 0 | M9: 0 | N9: 0 | O9: 0 | P9: 0 | Q9: 0 | R9: 13063 | S9: 10463 | T9: 0 | U9: 24357 | V9: 14766 | W9: 24174 | X9: 4720
A10: Calypso | B10: 53-100766 | C10: BR | D10: 0 | E10: 0 | F10: 0 | G10: 0 | H10: 0 | I10: 17839 | J10: 2670 | K10: 7854 | L10: 2664 | M10: 2648 | N10: 2656 | O10: 5555 | P10: 2639 | Q10: 0 | R10: 5439 | S10: 2769 | T10: 0 | U10: 35865 | V10: 5417 | W10: 5509 | X10: 12372
A11: Calypso | B11: 53-100767 | C11: MX | D11: 0 | E11: 1496 | F11: 4140 | G11: 5253 | H11: 5125 | I11: 4082 | J11: 1050 | K11: 46430 | L11: 2664 | M11: 2604 | N11: 2664 | O11: 2851 | P11: 2664 | Q11: 0 | R11: 2651 | S11: 12552 | T11: 26961 | U11: 8872 | V11: 5476 | W11: 3985 | X11: 8855
A12: Calypso | B12: 53-100769 | C12: ROW-DE | D12: 0 | E12: 0 | F12: 739 | G12: 475 | H12: 523 | I12: 493 | J12: 493 | K12: 537 | L12: 985 | M12: 1130 | N12: 1358 | O12: 1656 | P12: 2198 | Q12: 0 | R12: 981 | S12: 976 | T12: 931 | U12: 1217 | V12: 1379 | W12: 911 | X12: 923
A13: Calypso | B13: 53-101569 | C13: CA | D13: 0 | E13: 1622 | F13: 5549 | G13: 5490 | H13: 5517 | I13: 5603 | J13: 2499 | K13: 6546 | L13: 3315 | M13: 5249 | N13: 6992 | O13: 5472 | P13: 9127 | Q13: 0 | R13: 2676 | S13: 11315 | T13: 36794 | U13: 2865 | V13: 6934 | W13: 2749 | X13: 7033
Q14: =SUM(D14:P14) -> 0
B15: Weekly Cum | C15: (a) | D15: =SUM(D5:D13) -> 9575 | E15: =SUM(E5:E13) -> 67809 | F15: =SUM(F5:F13) -> 156261 | G15: =SUM(G5:G13) -> 199776 | H15: =SUM(H5:H13) -> 211002 | I15: =SUM(I5:I13) -> 211002 | J15: =SUM(J5:J13) -> 105501 | K15: =SUM(K5:K13) -> 211002 | ... X15: =SUM(X5:X13) -> 210994
B16: Cum | D16: =+D15 -> 9575 | E16: =D16+E15 -> 77384 | F16: =E16+F15 -> 233645 | G16: =F16+G15 -> 433421 | H16: =G16+H15 -> 644423 | I16: =H16+I15 -> 855425 | J16: =I16+J15 -> 960926 | K16: =J16+K15 -> 1171928 | L16: =K16+L15 -> 1330180 | ... X16: =W16+X15 -> 3441000
B18: Internal demand | C18: (b) | D18: ='Internal PO build'!D15 -> 1681
B20: Trial Run | C20: © | D20: =12*2 -> 24 | E20: =12*2 -> 24 | F20: =12 -> 12
C22: Ramp capacity (d) | D22: =SUM('Ramp up plan by line'!L52:Q52) -> 11109 | E22: =SUM('Ramp up plan by line'!S52:X52) -> 68871 | F22: =SUM('Ramp up plan by line'!Z52:AE52) -> 153713 | G22: =SUM('Ramp up plan by line'!AG52:AL52) -> 208526
C23: Gap (d) - (a+b+c) | D23: =D22-SUM(D15,D18,D20) -> -171 | E23: =E22-SUM(E15,E18,E20) -> 1038 | F23: =F22-SUM(F15,F18,F20) -> -2560 | G23: =G22-SUM(G15,G18,G20) -> 8750
C24: Cum | D24: =+D23 -> -171 | E24: =+D24+E23 -> 867 | F24: =+E24+F23 -> -1693 | G24: =+F24+G23 -> 7057

Sheet CTB status
B1: Calypso CTB summary based on 11/07 ver
B2: Project | C2: Item | D2: LPN | E2: Vendor | F2: Description | G2: PVT Shortage date (on CTB) | H2: CNT comments (PVT material status) | I2: Risk level
B3: Calypso | C3: SMT | D3: 17-004193 | E3: AMPHENOL | F3: ANTENNA,CERAMIC,DK30,SMT-2,(16.2x16.2x4. | G3: 46003 | H3: Amotech can't be used in DVT, need to ask SAA to pull in, next batch 85k ETA VN 12/18, 100k ETA VN 12/25, will keep tracking with supplier | I3: Middle
B4: Calypso | C4: SMT | D4: 15-001086 | E4: Nexperia | F4: DIODE,TVS,UNI-DIR,CAT-2,H/S,2020Q4,0201( | G4: 46015 | H4: Nexperia export control, can not support. Need to find 2nd source | I4: Middle
B5: Calypso | C5: SMT | D5: 14-010551 | E5: Silergy | F5: IC,PWR MONITOR,Vs=2.7V-5.5V,CMAI=0V-28V, | G5: 45983 | H5: Silergy replied they had shipped out the 15k materials. Checking with distributor about the ETA | I5: Low
F6: HSG

Sheet Capacity
B2: Case 1: 6 working days, Max WRR 211,002
B3: VN site | C3: SMT * 3A lines | F3: FATP * 4A lines | G3: Packing * 5M lines
B4: Items | C4: S1 (B+B) | D4: S2 (T+T) | E4: S12 (B+T) | F4: Fungible 1.0 | G4: Manual line
B5: UPH/line | C5: 1250 | D5: 1250 | E5: 460 | F5: 524 | G5: 411
B6: Line Qty | C6: 1 | D6: 1 | E6: 1 | F6: 4 | G6: 5
B7: Efficiency | C7: 0.9 | F7: 0.95 | G7: 1
B8: Yieldrate | C8: 0.995 | F8: 0.995 | G8: 1
B9: Working hours/day | C9: 24 | F9: 17.75 | G9: 17.75
B10: Working days/week | C10: 6 | F10: 6 | G10: 6
B11: DRR | C11: =INT(C5*C6*C7*C8*C9) -> 26865 | D11: =INT(D5*D6*C7*C8*C9) -> 26865 | E11: =INT(E5*E6*C7*C8*C9) -> 9886 | F11: =INT(F5*F6*F7*F8*F9) -> 35167 | G11: =INT(G5*G8*G6*G7*G9) -> 36476
B12: CUM DRR | C12: =D11+E11 -> 36751 | F12: =F11 -> 35167 | G12: =SUM(G11:G11) -> 36476
B13: WRR | C13: =C11*C10 -> 161190 | D13: =D11*C10 -> 161190 | E13: =E11*C10 -> 59316 | F13: =F11*F10 -> 211002 | G13: =G11*G10 -> 218856
B14: CUM WRR | C14: =SUM(D13:E13) -> 220506 | F14: =F13 -> 211002 | G14: =SUM(G13:G13) -> 218856
B16: Case 2: 7 working days, Max WRR 246,169
B17: VN site | C17: SMT * 3A lines | F17: FATP * 4A lines | G17: Packing * 5M lines
B18: Items | C18: S1 (B+B) | D18: S2 (T+T) | E18: S12 (B+T) | F18: Fungible 1.0 | G18: Manual line
B19: UPH/line | C19: 1250 | D19: 1250 | E19: 460 | F19: 524 | G19: 411
B20: Line Qty | C20: 1 | D20: 1 | E20: 1 | F20: 4 | G20: 5
B21: Efficiency | C21: 0.9 | F21: 0.95 | G21: 1
B22: Yieldrate | C22: 0.995 | F22: 0.995 | G22: 1
B23: Working hours/day | C23: 24 | F23: 17.75 | G23: 17.75
B24: Working days/week | C24: 7 | F24: 7 | G24: 7
B25: DRR | C25: =INT(C19*C20*C21*C22*C23) -> 26865 | D25: =INT(D19*D20*C21*C22*C23) -> 26865 | E25: =INT(E19*E20*C21*C22*C23) -> 9886 | F25: =INT(F19*F20*F21*F22*F23) -> 35167 | G25: =INT(G19*G22*G20*G21*G23) -> 36476
B26: CUM DRR | C26: =D25+E25 -> 36751 | F26: =F25 -> 35167 | G26: =SUM(G25:G25) -> 36476
B27: WRR | C27: =C25*C24 -> 188055 | D27: =D25*C24 -> 188055 | E27: =E25*C24 -> 69202 | F27: =F25*F24 -> 246169 | G27: =G25*G24 -> 255332
B28: CUM WRR | C28: =SUM(D27:E27) -> 257257 | F28: =F27 -> 246169 | G28: =SUM(G27:G27) -> 255332

Sheet Tooling status
B2: No. | C2: Site | D2: Part | E2: LPN | F2: Q'ty | G2: WRR/Tool | H2: Cum WRR (6 working days) | I2: Tooling status
B3: 1 | C3: VN | D3: Main housing | E3: 20-105049 | F3: 9 | G3: 38016 | H3: =+G3*F3 -> 342144 | I3: Divide into 3 batches: * Batch 1 = 3 Main housing (C01/C05/C06) + 3 Lid housing (C01/C06/C08). Copytool qualification on-going. Tooling ready to use date: 11/10 * Batch 2 = 3 Main housing (C03/C04/C07) + 3 Lid housing (C03/C04/C07). Copytool qualification on-going. Tooling ready to use date: 11/24 * Batch 3 = 3 Main housing (C06/C02/C05) + 2 Lid housing (C02/C09). Tooling ready to use date: 12/01 (with lid housing tool C08 which was qualified from Batch 1)
B4: 2 | D4: Housing lid | E4: 20-105053 | F4: 8 | G4: 40550 | H4: =+G4*F4 -> 324400
B6: ※ Risk: No risk so far. First batch's capacity can cover until the remaining tools got qualified
B7: ※ Remark:
B8: 1. Peak DRR 52,750 ,Peak WRR316,500
B9: 2. For Main housing * total 8 sets Copy tools+ 1set Engineering tool, for Housing lid * total 7 sets Copy tools+1 set Engineering tool.
B10: 3. Engineering tool need to be replaced with new Cavtiy & Slider by the MP artwork.
B12: ※ Capacity by batch:
B13: Batch # | C13: WRR | D13: Part | E13: LPN | F13: Q'ty | G13: WRR/Tool | H13: Cum WRR (6 working days) | I13: Remark
B14: 1 | C14: =MIN(H14,H15) -> 114048 | D14: Main housing | E14: 20-105049 | F14: 3 | G14: 38016 | H14: =+G14*F14 -> 114048
D15: Housing lid | E15: 20-105053 | F15: 3 | G15: 40550 | H15: =+G15*F15 -> 121650
B16: 2 | C16: =MIN(H16,H17) -> 114048 | D16: Main housing | E16: 20-105049 | F16: 3 | G16: 38016 | H16: =+G16*F16 -> 114048
D17: Housing lid | E17: 20-105053 | F17: 3 | G17: 40550 | H17: =+G17*F17 -> 121650
B18: 3 | C18: =MIN(H18,H19) -> 81100 | D18: Main housing | E18: 20-105049 | F18: 3 | G18: 38016 | H18: =+G18*F18 -> 114048 | I18: Will qualify with 1 lid housing tool which was qualified from Batch 1
D19: Housing lid | E19: 20-105053 | F19: 2 | G19: 40550 | H19: =+G19*F19 -> 81100

Sheet Copy tooling schedule
D2: OK2Tool | J2: 8/1 Get final logo artwork
D3: 45834 | E3: 45837 | F3: =E3+7 -> 45844 | G3: =F3+7 -> 45851 | H3: =G3+7 -> 45858 | I3: =H3+7 -> 45865 | J3: =I3+7 -> 45872 | K3: =J3+7 -> 45879 | L3: =K3+7 -> 45886 | M3: =L3+7 -> 45893 | ... AB3: =AA3+7 -> 45998
B4: weeks | D4: 0 | E4: 1 | F4: 2 | G4: 3 | H4: 4 | I4: 5 | J4: 6 | K4: 7 | L4: 8 | M4: 9 | N4: 10 | O4: 11 | P4: 12 | Q4: 13 | R4: 14 | S4: 15 | T4: 16 | U4: 17 | V4: 18 | W4: 19 | X4: 20 | Y4: 21 | Z4: 22 | AA4: 23 | AB4: 24
B5: Group | C5: Part Name
B6: 1 | C6: Engineering tool | D6: Modify Fabrication--Verify two gating solutions simultaneously (Original Engineering tool +one set of copy tool) | H6: T0 | I6: T1 trial | J6: Texture | K6: T2 | L6: TF/FAI/CMK | M6: LBU DVT 4K Molding in LH | N6: Improve cosmetic | P6: DVT main build | Q6: transfer to VN | R6: Tool trial FAI ,CPK,DVT 1K molding in VN | T6: Tool trial change PVT normal logo | U6: Control Run Molding in VN | V6: CNT FATP+HuaNan Measurement+RREL/ Drop & Tumble+Amazon approve | X6: Ramp up
B7: 2 | C7: Copy Tools: 4 sets Main housing + 4 sets Housing lid | E7: Modify Fabrication | I7: Waiting for gate verification results | K7: Complete the reserved processing+T0 | M7: T1 | N7: Wait for the engineering tool improve cosmetic result | P7: Texture | Q7: T2 | R7: TF,FAI/CMK | S7: National Day | T7: transfer VN, TF/FAI/CMK | W7: Control Run Molding in VN | X7: CNT FATP+HuaNan Measurement+RREL/ Drop & Tumble+Amazon approve | Z7: Ramp up
B8: 3 | C8: Copy Tools: 4 sets Main housing + 3 sets Housing lid | F8: Modify Fabrication | J8: Waiting for gate verification results | L8: Complete the reserved processing+T0 | N8: T1 | O8: Wait for the engineering tool improve cosmetic result | P8: Waiting in line for Texture | Q8: Texture | R8: T2 | T8: TF,FAI/CMK | U8: transfer VN, TF/FAI/CMK | X8: Control Run Molding in VN | Y8: CNT FATP+HuaNan Measurement+RREL/ Drop & Tumble+Amazon approve | AA8: Ramp up
B15: Remark:
B16: 1. Copy tool kick off by 2 group, Main housing 8sets, Housing lid 7sets
B17: 2. Group1& Group2 MP in VN,
B18: 3. The above Schedule does not include holidays.
B19: 4. If there is design modify, the time will be calculated separately.

Sheet BOM Matrix
B3: Project | C3: Region | D3: 53- PN | E3: 52-PN | F3: 31-PN | G3: Remote | H3: Cable | I3: Pallet q'ty | J3: If have FCST | K3: ASIN | L3: UPC | M3: Packout start date | N3: Build qty (from PVT to OK2ship)
B4: Calypso | C4: US | D4: 53-100275 | E4: 52-100667 | F4: 31-101122 | G4: 52-006181 (primary) 52-100494 (alternate) | H4: 55-100633 | I4: =6*37*12 -> 2664 | J4: Y | K4: B0DJGDC3BD | L4: 840414612631 | M4: 45973 | N4: =229406+952 -> 230358
C5: DE-FR-IT-ES-GB-IE | D5: 53-100276 | E5: 52-100667 | F5: 31-101122 | G5: 52-006182 | H5: 55-100633 | I5: =6*37*12 -> 2664 | J5: Y | K5: B0DJGCX6Q2 | L5: 840414634510 | M5: 45979 | N5: =28791+354 -> 29145
C6: AU | D6: 53-100763 | E6: 52-100667 | F6: 31-101122 | G6: 52-006182 | H6: 55-100633 | I6: =6*37*12 -> 2664 | J6: Y | K6: B0DVJ8VJT7 | L6: 840414664043 | M6: 45981 | N6: 49
C7: JP | D7: 53-100764 | E7: 52-100667 | F7: 31-101122 | G7: 52-005905 | H7: 55-100633 | I7: =6*73*6 -> 2628 | J7: Y | K7: B0DVJ64ZLT | L7: 840414695122 | M7: 45981 | N7: =5256+61 -> 5317
C8: IN | D8: 53-100765 | E8: 52-100667 | F8: 31-101122 | G8: 52-100663 | H8: 55-100633 | I8: =6*73*6 -> 2628 | J8: Y | K8: B0DVJF7528 | L8: 840414652538 | M8: 45980 | N8: 79
C9: BR | D9: 53-100766 | E9: 52-100667 | F9: 31-101122 | G9: 52-100502 (primary) 52-100617 (alternate) | H9: 55-100633 | I9: =6*37*12 -> 2664 | J9: Y | K9: B0DVK166SV | L9: 840414689107 | M9: 45982 | N9: 58
C10: MX | D10: 53-100767 | E10: 52-100667 | F10: 31-101122 | G10: 52-100500 (primary) 52-100615 (alternate) | H10: 55-100633 | I10: =6*37*12 -> 2664 | J10: Y | K10: B0DVJX97PM | L10: 840414612198 | M10: 45982 | N10: 58
C11: NL-PL-SE-ROW | D11: 53-100769 | E11: 52-100667 | F11: 31-101122 | G11: 52-100501 (primary) 52-100619 (alternate) | H11: 55-100633 | I11: =6*37*12 -> 2664 | J11: Y | K11: B0DVK2RPFK | L11: 840414684737 | M11: 45981 | N11: 8
C12: CA | D12: 53-101569 | E12: 52-100667 | F12: 31-101122 | G12: 52-100498 (primary) 52-100611 (alternate) | H12: 55-100633 | I12: =6*37*12 -> 2664 | J12: Y | K12: B0F7K67DY2 | L12: 840414698758 | M12: 45982 | N12: 62

Sheet Pre-seal OBA plan 
D2: Mon | E2: Tue | F2: Wed | G2: Thu | H2: Fri | I2: Sat | J2: Sun | K2: Mon | L2: Tue | M2: Wed | N2: Thu | O2: Fri | P2: Sat | Q2: Sun | R2: Mon | S2: Tue | T2: Wed | U2: Thu | V2: Fri | W2: Sat | X2: Sun | Y2: Mon | Z2: Tue
D3: 45740 | E3: 45741 | F3: 45742 | G3: 45743 | H3: 45744 | I3: 45745 | J3: 45746 | K3: 45747 | L3: 45748 | M3: 45749 | N3: 45750 | O3: 45751 | P3: 45752 | Q3: 45753 | R3: 45754 | S3: 45755 | T3: 45756 | U3: 45757 | V3: 45758 | W3: 45759 | X3: 45760 | Y3: 45761 | Z3: 45762
B4: OBA capacity by Daily | C4: 100% inspection Q`ty | D4: 663 | F4: 663 | H4: 663 | K4: 663
C5: Normal Sampling Q`ty | D5: 3 | E5: 0 | F5: 34 | G5: 51 | H5: 104 | I5: 135 | J5: 0 | K5: 205 | L5: 253 | M5: 337 | N5: 396 | O5: 0 | P5: 455 | Q5: 0 | R5: 506 | S5: 548 | T5: 581 | U5: 607 | V5: 624 | W5: 632 | X5: 0 | Y5: 640 | Z5: 640
C6: UPH | D6: 2 | E6: 2 | F6: 2 | G6: 2 | H6: 2 | I6: 2 | J6: 2 | K6: 2 | L6: 2 | M6: 2 | N6: 2 | O6: 2 | P6: 2 | Q6: 2 | R6: 2 | S6: 2 | T6: 2 | U6: 2 | V6: 2 | W6: 2 | X6: 2 | Y6: 2 | Z6: 2
C7: Work position | D7: 24 | E7: 24 | F7: 24 | G7: 24 | H7: 24 | I7: 24 | J7: 24 | K7: 24 | L7: 24 | M7: 24 | N7: 24 | O7: 24 | P7: 24 | Q7: 24 | R7: 24 | S7: 24 | T7: 24 | U7: 24 | V7: 24 | W7: 24 | X7: 24 | Y7: 24 | Z7: 24
C8: Ramp UP | D8: 0.9 | E8: 0.9 | F8: 0.9 | G8: 0.95 | H8: 0.95 | I8: 0.95 | J8: 1 | K8: 1 | L8: 1 | M8: 1 | N8: 1 | O8: 1 | P8: 1 | Q8: 1 | R8: 1 | S8: 1 | T8: 1 | U8: 1 | V8: 1 | W8: 1 | X8: 1 | Y8: 1 | Z8: 1
C9: work hour | D9: 19 | E9: 19 | F9: 19 | G9: 19 | H9: 19 | I9: 19 | J9: 19 | K9: 19 | L9: 19 | M9: 19 | N9: 19 | O9: 19 | P9: 19 | Q9: 19 | R9: 19 | S9: 19 | T9: 19 | U9: 19 | V9: 19 | W9: 19 | X9: 19 | Y9: 19 | Z9: 19
